{
 "cells": [
  {
   "cell_type": "code",
   "execution_count": 6,
   "metadata": {},
   "outputs": [
    {
     "name": "stdout",
     "output_type": "stream",
     "text": [
      "hi\n"
     ]
    }
   ],
   "source": [
    "print(\"hi\")\n"
   ]
  },
  {
   "cell_type": "code",
   "execution_count": 7,
   "metadata": {},
   "outputs": [
    {
     "name": "stdout",
     "output_type": "stream",
     "text": [
      "hi\n"
     ]
    }
   ],
   "source": [
    "print(\"hi\")"
   ]
  },
  {
   "cell_type": "code",
   "execution_count": 5,
   "metadata": {},
   "outputs": [],
   "source": [
    "import pandas as pd"
   ]
  },
  {
   "cell_type": "code",
   "execution_count": 2,
   "metadata": {},
   "outputs": [
    {
     "name": "stdout",
     "output_type": "stream",
     "text": [
      "Collecting Enum\n",
      "  Using cached enum-0.4.7.tar.gz (20 kB)\n",
      "  Preparing metadata (setup.py) ... \u001b[?25lerror\n",
      "  \u001b[1;31merror\u001b[0m: \u001b[1msubprocess-exited-with-error\u001b[0m\n",
      "  \n",
      "  \u001b[31m×\u001b[0m \u001b[32mpython setup.py egg_info\u001b[0m did not run successfully.\n",
      "  \u001b[31m│\u001b[0m exit code: \u001b[1;36m1\u001b[0m\n",
      "  \u001b[31m╰─>\u001b[0m \u001b[31m[8 lines of output]\u001b[0m\n",
      "  \u001b[31m   \u001b[0m Traceback (most recent call last):\n",
      "  \u001b[31m   \u001b[0m   File \"<string>\", line 2, in <module>\n",
      "  \u001b[31m   \u001b[0m   File \"<pip-setuptools-caller>\", line 11, in <module>\n",
      "  \u001b[31m   \u001b[0m   File \"/Users/gabrielvictorgomesferreira/opt/anaconda3/lib/python3.8/tokenize.py\", line 32, in <module>\n",
      "  \u001b[31m   \u001b[0m     import re\n",
      "  \u001b[31m   \u001b[0m   File \"/Users/gabrielvictorgomesferreira/opt/anaconda3/lib/python3.8/re.py\", line 145, in <module>\n",
      "  \u001b[31m   \u001b[0m     class RegexFlag(enum.IntFlag):\n",
      "  \u001b[31m   \u001b[0m AttributeError: module 'enum' has no attribute 'IntFlag'\n",
      "  \u001b[31m   \u001b[0m \u001b[31m[end of output]\u001b[0m\n",
      "  \n",
      "  \u001b[1;35mnote\u001b[0m: This error originates from a subprocess, and is likely not a problem with pip.\n",
      "\u001b[?25h\u001b[1;31merror\u001b[0m: \u001b[1mmetadata-generation-failed\u001b[0m\n",
      "\n",
      "\u001b[31m×\u001b[0m Encountered error while generating package metadata.\n",
      "\u001b[31m╰─>\u001b[0m See above for output.\n",
      "\n",
      "\u001b[1;35mnote\u001b[0m: This is an issue with the package mentioned above, not pip.\n",
      "\u001b[1;36mhint\u001b[0m: See above for details.\n",
      "\n",
      "\u001b[1m[\u001b[0m\u001b[34;49mnotice\u001b[0m\u001b[1;39;49m]\u001b[0m\u001b[39;49m A new release of pip is available: \u001b[0m\u001b[31;49m24.0\u001b[0m\u001b[39;49m -> \u001b[0m\u001b[32;49m24.2\u001b[0m\n",
      "\u001b[1m[\u001b[0m\u001b[34;49mnotice\u001b[0m\u001b[1;39;49m]\u001b[0m\u001b[39;49m To update, run: \u001b[0m\u001b[32;49mpip install --upgrade pip\u001b[0m\n",
      "Note: you may need to restart the kernel to use updated packages.\n"
     ]
    }
   ],
   "source": [
    "pip install Enum"
   ]
  },
  {
   "cell_type": "code",
   "execution_count": null,
   "metadata": {},
   "outputs": [],
   "source": []
  }
 ],
 "metadata": {
  "kernelspec": {
   "display_name": "base",
   "language": "python",
   "name": "python3"
  },
  "language_info": {
   "codemirror_mode": {
    "name": "ipython",
    "version": 3
   },
   "file_extension": ".py",
   "mimetype": "text/x-python",
   "name": "python",
   "nbconvert_exporter": "python",
   "pygments_lexer": "ipython3",
   "version": "3.8.16"
  }
 },
 "nbformat": 4,
 "nbformat_minor": 2
}
